Workbook

Sheet Index
A7: Tab Name | B7: Description | C7: Link
A8: PL | B8: Profit and Loss | C8: PL!A1
A9: BS | B9: Balance Sheet | C9: BS!A1
A10: CFS | B10: Cash Flow Statement | C10: CFS!A1
A11: Ethanol | B11: Ethanol and DDGS working | C11: Ethanol!A1
A12: Sugar | B12: Sugar plant working | C12: Sugar!A1
A13: Power | B13: Bagasse based plant working | C13: Power!A1
A14: Employee | B14: Employee cost | C14: Employee!A1

Sheet Summary
B2: Particulars | C2: 45747 | D2: =EOMONTH(C2,12) -> 46112 | E2: =EOMONTH(D2,12) -> 46477 | F2: =EOMONTH(E2,12) -> 46843 | G2: =EOMONTH(F2,12) -> 47208 | H2: =EOMONTH(G2,12) -> 47573 | K2: CAGR
B3: Revenue from Operations | C3: =2960217280.04+41806415 -> 3.0020237e+09 | D3: =PL!I$17 -> 8.1107688e+09 | E3: =PL!N17 -> 1.3105576e+10 | F3: =PL!S17 -> 1.3784026e+10 | G3: =PL!X17 -> 1.4622741e+10 | H3: =PL!AC17 -> 1.5649111e+10
B4: Total Revenue | C4: =SUM(C3:C3) -> 3.0020237e+09 | D4: =SUM(D3:D3) -> 8.1107688e+09 | E4: =SUM(E3:E3) -> 1.3105576e+10 | F4: =SUM(F3:F3) -> 1.3784026e+10 | G4: =SUM(G3:G3) -> 1.4622741e+10 | H4: =SUM(H3:H3) -> 1.5649111e+10 | I4: =H4/C4 -> 5.2128541 | K4: =(H4/C4)^(1/5)-1 -> 0.39128183
B6: Expenses:
B7: Cost of materials consumed | C7: =2596066425.97-399258751 -> 2.1968077e+09 | D7: =SUM(D8:D9) -> 6.2159227e+09 | E7: =SUM(E8:E9) -> 9.8303908e+09 | F7: =SUM(F8:F9) -> 9.7282752e+09 | G7: =SUM(G8:G9) -> 1.0221874e+10 | H7: =SUM(H8:H9) -> 1.0952647e+10 | I7: =E7/$E$4 -> 0.75009221 | J7: =F7/$F$4 -> 0.70576442
B8: Sugercane | C8: 0 | D8: =SUM(PL!$I$21:$I$26) -> 2.4107063e+09 | E8: =SUM(PL!$N$21:$N$26) -> 2.1584944e+09 | F8: =SUM(PL!$S$21:$S$26) -> 2.284255e+09 | G8: =SUM(PL!$X$21:$X$26) -> 2.6301462e+09 | H8: =SUM(PL!$AC$21:$AC$26) -> 3.1285798e+09 | I8: =E8/$E$4 -> 0.16470045 | J8: =F8/$F$4 -> 0.16571754
B9: Corn | C9: 0 | D9: =SUM(PL!$I$29:$I$34) -> 3.8052164e+09 | E9: =SUM(PL!$N$29:$N$34) -> 7.6718965e+09 | F9: =SUM(PL!$S$29:$S$34) -> 7.4440202e+09 | G9: =SUM(PL!$X$29:$X$34) -> 7.5917275e+09 | H9: =SUM(PL!$AC$29:$AC$34) -> 7.8240671e+09 | I9: =E9/$E$4 -> 0.58539176 | J9: =F9/$F$4 -> 0.54004688
B10: Salaries Corporate Employees | C10: 84408959 | D10: =PL!$I$37 -> 28022816 | E10: =PL!$N$37 -> 30931945 | F10: =PL!$S$37 -> 34143080 | G10: =PL!$X$37 -> 37687572 | H10: =PL!$AC$37 -> 41600027 | I10: =E10/$E$4 -> 0.0023602125 | J10: =F10/$F$4 -> 0.0024770034
B11: Research Expenses | C11: 0 | D11: =PL!$I$38 -> 4152515.6 | E11: =PL!$N$38 -> 4583600.3 | F11: =PL!$S$38 -> 5059437.1 | G11: =PL!$X$38 -> 5584671.9 | H11: =PL!$AC$38 -> 6164432.8 | I11: =E11/$E$4 -> 0.00034974427 | J11: =F11/$F$4 -> 0.00036705075
B12: Misc Expenses | C12: 0 | D12: =PL!$I$39 -> 20608040 | E12: =PL!$N$39 -> 22306805 | F12: =PL!$S$39 -> 24145603 | G12: =PL!$X$39 -> 26135978 | H12: =PL!$AC$39 -> 28290423 | I12: =E12/$E$4 -> 0.001702085 | J12: =F12/$F$4 -> 0.0017517091
B13: Sales and marketing Expenses | C13: 48003432 | D13: =PL!$I$40 -> 1.2389657e+08 | E13: =PL!$N$40 -> 2.5603886e+08 | F13: =PL!$S$40 -> 2.6315607e+08 | G13: =PL!$X$40 -> 2.7027021e+08 | H13: =PL!$AC$40 -> 2.7738435e+08 | I13: =E13/$E$4 -> 0.019536635 | J13: =F13/$F$4 -> 0.019091379
B14: Total Expenses | C14: =SUM(C7:C13) -> 2.3292201e+09 | D14: =SUM(D7,D10:D13) -> 6.3926026e+09 | E14: =SUM(E7,E10:E13) -> 1.0144252e+10 | F14: =SUM(F7,F10:F13) -> 1.0054779e+10 | G14: =SUM(G7,G10:G13) -> 1.0561552e+10 | H14: =SUM(H7,H10:H13) -> 1.1306086e+10 | K14: =(H14/C14)^(1/5)-1 -> 0.3715775
N15: 3.0020237e+09 | O15: 8.1107688e+09 | P15: 1.3105576e+10 | Q15: 1.3784026e+10 | R15: 1.4622741e+10 | S15: 1.5649111e+10
B16: EBITDA | C16: =C4-C14 -> 6.7280363e+08 | D16: =D4-D14 -> 1.7181662e+09 | E16: =E4-E14 -> 2.9613244e+09 | F16: =F4-F14 -> 3.7292467e+09 | G16: =G4-G14 -> 4.0611889e+09 | H16: =H4-H14 -> 4.3430253e+09 | I16: =H16/C16 -> 6.4551157 | J16: =(H16/D16)^(1/4)-1 -> 0.26090334 | K16: =(H16/C16)^(1/5)-1 -> 0.45204744 | N16: =N15/10^7 -> 300.20237 | O16: =O15/10^7 -> 811.07688 | P16: =P15/10^7 -> 1310.5576 | Q16: =Q15/10^7 -> 1378.4026 | R16: =R15/10^7 -> 1462.2741 | S16: =S15/10^7 -> 1564.9111
B17: Depreciation and Amortization Expense | C17: 126822429 | D17: =PL!I46 -> 3.1687701e+08 | E17: =PL!N46 -> 4.0684539e+08 | F17: =PL!S46 -> 3.4916633e+08 | G17: =PL!X46 -> 2.9966451e+08 | H17: =PL!AC46 -> 2.5718063e+08 | N17: 300.20237 | O17: 811.07688 | P17: 1310.5576 | Q17: 1378.4026 | R17: 1462.2741 | S17: 1564.9111
B18: Financial Costs | C18: 1.1393948e+08 | D18: =PL!I$47 -> 3.7964981e+08 | E18: =PL!N47 -> 2.8096845e+08 | F18: =PL!S47 -> 79287497 | G18: =PL!X47 -> 68670364 | H18: =PL!AC47 -> 57401725 | N18: 6.7280363e+08 | O18: 1.7181662e+09 | P18: 2.9613244e+09 | Q18: 3.7292467e+09 | R18: 4.0611889e+09 | S18: 4.3430253e+09
B19: PBT | C19: =C16-SUM(C17:C18) -> 4.3204172e+08 | D19: =D16-SUM(D17:D18) -> 1.0216394e+09 | E19: =E16-SUM(E17:E18) -> 2.2735106e+09 | F19: =F16-SUM(F17:F18) -> 3.3007928e+09 | G19: =G16-SUM(G17:G18) -> 3.692854e+09 | H19: =H16-SUM(H17:H18) -> 4.0284429e+09 | K19: =(H19/C19)^(1/5)-1 -> 0.56286803 | N19: =N18/10^7 -> 67.280363 | O19: =O18/10^7 -> 171.81662 | P19: =P18/10^7 -> 296.13244 | Q19: =Q18/10^7 -> 372.92467 | R19: =R18/10^7 -> 406.11889 | S19: =S18/10^7 -> 434.30253
B20: less:Taxes | C20: 1.0001958e+08 | D20: =PL!I51 -> 2.5714664e+08 | E20: =PL!N51 -> 5.7224261e+08 | F20: =PL!S51 -> 8.3080956e+08 | G20: =PL!X51 -> 9.2949136e+08 | H20: =PL!AC51 -> 1.0139591e+09 | N20: 67.280363 | O20: 171.81662 | P20: 296.13244 | Q20: 372.92467 | R20: 406.11889 | S20: 434.30253
B21: PAT | C21: =C19-C20 -> 3.3202214e+08 | D21: =D19-D20 -> 7.6449276e+08 | E21: =E19-E20 -> 1.701268e+09 | F21: =F19-F20 -> 2.4699833e+09 | G21: =G19-G20 -> 2.7633627e+09 | H21: =H19-H20 -> 3.0144838e+09 | I21: =H21/C21 -> 9.0791651 | K21: =(H21/C21)^(1/5)-1 -> 0.55456606 | N21: 3.3202214e+08 | O21: 7.6449276e+08 | P21: 1.701268e+09 | Q21: 2.4699833e+09 | R21: 2.7633627e+09 | S21: 3.0144838e+09
N22: =N21/10^7 -> 33.202214 | O22: =O21/10^7 -> 76.449276 | P22: =P21/10^7 -> 170.1268 | Q22: =Q21/10^7 -> 246.99833 | R22: =R21/10^7 -> 276.33627 | S22: =S21/10^7 -> 301.44838
N23: 33.202214 | O23: 76.449276 | P23: 170.1268 | Q23: 246.99833 | R23: 276.33627 | S23: 301.44838
O25: Revenue | P25: EBITDA | Q25: PAT | R25: PAT Margin | S25: EBITDA Margin
N26: 2025 | O26: =$N17 -> 300.20237 | P26: =N20 -> 67.280363 | Q26: =N23 -> 33.202214 | R26: =Q26/O26 -> 0.11059944 | S26: =P26/O26 -> 0.22411669
B27: Ratio | C27: 45747 | D27: =EOMONTH(C27,12) -> 46112 | E27: =EOMONTH(D27,12) -> 46477 | F27: =EOMONTH(E27,12) -> 46843 | G27: =EOMONTH(F27,12) -> 47208 | H27: =EOMONTH(G27,12) -> 47573 | K27: Formula | N27: =N26+1 -> 2026 | O27: =O17 -> 811.07688 | P27: =O20 -> 171.81662 | Q27: =O23 -> 76.449276 | R27: =Q27/O27 -> 0.09425651 | S27: =P27/O27 -> 0.21183765
B28: Profitability | N28: =N27+1 -> 2027 | O28: =P17 -> 1310.5576 | P28: =P20 -> 296.13244 | Q28: =P23 -> 170.1268 | R28: =Q28/O28 -> 0.12981252 | S28: =P28/O28 -> 0.22595911
B29: Operating margins | C29: =C16/C3 -> 0.22411669 | D29: =D16/D3 -> 0.21183765 | E29: =E16/E3 -> 0.22595911 | F29: =F16/F3 -> 0.27054843 | G29: =G16/G3 -> 0.27773103 | H29: =H16/H3 -> 0.27752536 | K29: EBITDA/Sales | N29: =N28+1 -> 2028 | O29: =Q17 -> 1378.4026 | P29: =Q20 -> 372.92467 | Q29: =Q23 -> 246.99833 | R29: =Q29/O29 -> 0.17919172 | S29: =P29/O29 -> 0.27054843
B30: NPM | C30: =C21/C3 -> 0.11059944 | D30: =D21/D3 -> 0.09425651 | E30: =E21/E3 -> 0.12981252 | F30: =F21/F3 -> 0.17919172 | G30: =G21/G3 -> 0.18897706 | H30: =H21/H3 -> 0.19262971 | K30: PAT/Sales | N30: =N29+1 -> 2029 | O30: =R17 -> 1462.2741 | P30: =R20 -> 406.11889 | Q30: =R23 -> 276.33627 | R30: =Q30/O30 -> 0.18897706 | S30: =P30/O30 -> 0.27773103
N31: =N30+1 -> 2030 | O31: =S17 -> 1564.9111 | P31: =S20 -> 434.30253 | Q31: =S23 -> 301.44838 | R31: =Q31/O31 -> 0.19262971 | S31: =P31/O31 -> 0.27752536
B32: Return ratio
B33: Return on Equity | C33: =C21/BS!C41 -> 0.26996963 | D33: =D21/BS!H41 -> 0.38333069 | E33: =E21/BS!L41 -> 0.46034826 | F33: =F21/BS!P41 -> 0.40060752 | G33: =G21/BS!T41 -> 0.30948327 | H33: =H21/BS!X41 -> 0.25239661 | K33: PAT/Total Equity
B34: Return on capital employed | C34: =C16/(BS!C25+BS!C31+BS!C41) -> 0.15509895 | D34: =D16/(BS!H25+BS!H31+BS!H41) -> 0.29495263 | E34: =E16/(BS!L25+BS!L31+BS!L41) -> 0.49027568 | F34: =F16/(BS!P25+BS!P31+BS!P41) -> 0.44730827 | G34: =G16/(BS!T25+BS!T31+BS!T41) -> 0.37201244 | H34: =H16/(BS!X25+BS!X31+BS!X41) -> 0.3161694 | K34: EBITDA/(Total Debt+Equity)
B36: Debt ratio
B37: Debt/equity | C37: =(BS!C25+BS!C31)/BS!C41 -> 2.5271777 | D37: =(BS!H25+BS!H31)/BS!H41 -> 1.920876 | E37: =(BS!L25+BS!L31)/BS!L41 -> 0.63440401 | F37: =(BS!P25+BS!P31)/BS!P41 -> 0.35219479 | G37: =(BS!T25+BS!T31)/BS!T41 -> 0.2226299 | H37: =(BS!X25+BS!X31)/BS!X41 -> 0.15011979 | K37: Total Debt/Equity
B38: interst coverage ratio | C38: =C16/C18 -> 5.9049209 | D38: =D16/D18 -> 4.5256607 | E38: =E16/E18 -> 10.539704 | F38: =F16/F18 -> 47.034486 | G38: =G16/G18 -> 59.140344 | H38: =H16/H18 -> 75.660187 | K38: EBITDA/Finance Cost
B40: Turnover ratio
B41: Fixed assets turnover | C41: =C3/(BS!C16+BS!C17) -> 1.0222773 | D41: =D3/(BS!H16+BS!H17) -> 2.8263207 | E41: =E3/(BS!L16+BS!L17) -> 5.3212368 | F41: =F3/(BS!P16+BS!P17) -> 6.5212311 | G41: =G3/(BS!T16+BS!T17) -> 8.0608222 | H41: =H3/(BS!X16+BS!X17) -> 10.051648 | K41: Sales/Total fixed assets
B42: inventory turnover | C42: =C3/BS!C11 -> 1.8699167 | D42: =D3/BS!H11 -> 6.565099 | E42: =E3/BS!L11 -> 2.8707071 | F42: =F3/BS!P11 -> 2.8492717 | G42: =G3/BS!T11 -> 2.7624593 | H42: =H3/BS!X11 -> 2.7464649 | K42: Sales/ inventory
B43: Receivable turnover | C43: =C3/BS!C10 -> 17.365832 | D43: =D3/BS!H10 -> 12.923054 | E43: =E3/BS!L10 -> 20.228256 | F43: =F3/BS!P10 -> 20.661752 | G43: =G3/BS!T10 -> 21.276137 | H43: =H3/BS!X10 -> 18.422904 | K43: Sales/ Receivable
B44: Payables turnover | C44: Sales/ Paybale | D44: =C3/BS!C26 -> 4.4049521 | E44: =D3/BS!H26 -> 40.46862 | F44: =E3/BS!L26 -> 23466.698 | G44: =F3/BS!P26 -> 22675.977 | H44: =G3/BS!T26 -> 21970.125 | I44: =H3/BS!X26 -> 17381.379
B47: Dupont analysis
...

Sheet PL
H1: =365*1.33/4 -> 121.3625
B2: No..of days of operation(days) | E2: =300/4 -> 75 | F2: =300/4 -> 75 | G2: =300/4 -> 75 | H2: =300/4 -> 75 | J2: =300/4 -> 75 | K2: =300/4 -> 75 | L2: =300/4 -> 75 | M2: =300/4 -> 75 | O2: =300/4 -> 75 | P2: =300/4 -> 75 | Q2: =300/4 -> 75 | R2: =300/4 -> 75 | T2: =300/4 -> 75 | U2: =300/4 -> 75 | V2: =300/4 -> 75 | W2: =300/4 -> 75 | Y2: =300/4 -> 75 | Z2: =300/4 -> 75 | AA2: =300/4 -> 75 | AB2: =300/4 -> 75
B3: Column counter | E3: 1 | F3: =E3+1 -> 2 | G3: =F3+1 -> 3 | H3: =G3+1 -> 4 | J3: =H3+1 -> 5 | K3: =J3+1 -> 6 | L3: =K3+1 -> 7 | M3: =L3+1 -> 8 | O3: =M3+1 -> 9 | P3: =O3+1 -> 10 | Q3: =P3+1 -> 11 | R3: =Q3+1 -> 12 | T3: =R3+1 -> 13 | U3: =T3+1 -> 14 | V3: =U3+1 -> 15 | W3: =V3+1 -> 16 | Y3: =W3+1 -> 17 | Z3: =Y3+1 -> 18 | AA3: =Z3+1 -> 19 | AB3: =AA3+1 -> 20
B4: Particulars | E4: 45838 | F4: =EOMONTH(E4,3) -> 45930 | G4: =EOMONTH(F4,3) -> 46022 | H4: =EOMONTH(G4,3) -> 46112 | I4: FY 25-26 | J4: =EOMONTH(H4,3) -> 46203 | K4: =EOMONTH(J4,3) -> 46295 | L4: =EOMONTH(K4,3) -> 46387 | M4: =EOMONTH(L4,3) -> 46477 | N4: FY 26-27 | O4: =EOMONTH(M4,3) -> 46568 | P4: =EOMONTH(O4,3) -> 46660 | Q4: =EOMONTH(P4,3) -> 46752 | R4: =EOMONTH(Q4,3) -> 46843 | S4: FY 27-28 | T4: =EOMONTH(R4,3) -> 46934 | U4: =EOMONTH(T4,3) -> 47026 | V4: =EOMONTH(U4,3) -> 47118 | W4: =EOMONTH(V4,3) -> 47208 | X4: FY 28-29 | Y4: =EOMONTH(W4,3) -> 47299 | Z4: =EOMONTH(Y4,3) -> 47391 | AA4: =EOMONTH(Z4,3) -> 47483 | AB4: =EOMONTH(AA4,3) -> 47573 | AC4: FY 29-30
A6: # | B6: Sale Sugar Plant
B7: Sale of Sugar | E7: =Sugar!E71 -> 7.8696429e+08 | F7: =Sugar!F71 -> 9.4157143e+08 | G7: =Sugar!G71 -> 5.9347857e+08 | H7: =Sugar!H71 -> 5.9060957e+08 | I7: =SUM(E7:H7) -> 2.9126239e+09 | J7: =Sugar!J71 -> 689044500 | K7: =Sugar!K71 -> 620140050 | L7: =Sugar!L71 -> 656942670 | M7: =Sugar!M71 -> 7.1917289e+08 | N7: =SUM(J7:M7) -> 2.6853001e+09 | O7: =Sugar!O71 -> 7.3006945e+08 | P7: =Sugar!P71 -> 6.570625e+08 | Q7: =Sugar!Q71 -> 7.7340417e+08 | R7: =Sugar!R71 -> 8.3025452e+08 | S7: =SUM(O7:R7) -> 2.9907906e+09 | T7: =Sugar!T71 -> 8.4283413e+08 | U7: =Sugar!U71 -> 7.5855072e+08 | V7: =Sugar!V71 -> 8.4401005e+08 | W7: =Sugar!W71 -> 1.0060992e+09 | X7: =SUM(T7:W7) -> 3.4514941e+09 | Y7: =Sugar!Y71 -> 1.0213431e+09 | Z7: =Sugar!Z71 -> 9.1920879e+08 | AA7: =Sugar!AA71 -> 9.2768059e+08 | AB7: =Sugar!AB71 -> 1.2119295e+09 | AC7: =SUM(Y7:AB7) -> 4.080162e+09
B8: Molasses | E8: =Sugar!E72 -> 42900000 | F8: =Sugar!F72 -> 38610000 | G8: =Sugar!G72 -> 1.03224e+08 | H8: =Sugar!H72 -> 106959600 | I8: =SUM(E8:H8) -> 291693600 | J8: =Sugar!J72 -> 35653200 | K8: =Sugar!K72 -> 32087880 | L8: =Sugar!L72 -> 109772256 | M8: =Sugar!M72 -> 1.3229584e+08 | N8: =SUM(J8:M8) -> 3.0980917e+08 | O8: =Sugar!O72 -> 44098613 | P8: =Sugar!P72 -> 39688752 | Q8: =Sugar!Q72 -> 1.3024789e+08 | R8: =Sugar!R72 -> 1.5259318e+08 | S8: =SUM(O8:R8) -> 3.6662844e+08 | T8: =Sugar!T72 -> 50864394 | U8: =Sugar!U72 -> 45777955 | V8: =Sugar!V72 -> 1.4187715e+08 | W8: =Sugar!W72 -> 1.8665117e+08 | X8: =SUM(T8:W8) -> 4.2517067e+08 | Y8: =Sugar!Y72 -> 62217058 | Z8: =Sugar!Z72 -> 55995352 | AA8: =Sugar!AA72 -> 1.5545736e+08 | AB8: =Sugar!AB72 -> 2.264666e+08 | AC8: =SUM(Y8:AB8) -> 5.0013638e+08
B9: Press Mud | E9: =Sugar!E74 -> 0 | F9: =Sugar!F74 -> 0 | G9: =Sugar!G74 -> 9072000 | H9: =Sugar!H74 -> 11088000 | I9: =SUM(E9:H9) -> 20160000 | J9: =Sugar!J74 -> 0 | K9: =Sugar!K74 -> 0 | L9: =Sugar!L74 -> 9720000 | M9: =Sugar!M74 -> 14040000 | N9: =SUM(J9:M9) -> 23760000 | O9: =Sugar!O74 -> 0 | P9: =Sugar!P74 -> 0 | Q9: =Sugar!Q74 -> 11520000 | R9: =Sugar!R74 -> 16128000 | S9: =SUM(O9:R9) -> 27648000 | T9: =Sugar!T74 -> 0 | U9: =Sugar!U74 -> 0 | V9: =Sugar!V74 -> 12528000 | W9: =Sugar!W74 -> 20044800 | X9: =SUM(T9:W9) -> 32572800 | Y9: =Sugar!Y74 -> 0 | Z9: =Sugar!Z74 -> 0 | AA9: =Sugar!AA74 -> 13680000 | AB9: =Sugar!AB74 -> 24624000 | AC9: =SUM(Y9:AB9) -> 38304000
B10: Bagasse | E10: =Sugar!E73 -> 0 | F10: =Sugar!F73 -> 0 | G10: =Sugar!G73 -> 0 | H10: =Sugar!H73 -> 0 | I10: =SUM(E10:H10) -> 0 | J10: =Sugar!J73 -> 0 | K10: =Sugar!K73 -> 0 | L10: =Sugar!L73 -> 0 | M10: =Sugar!M73 -> 0 | N10: =SUM(J10:M10) -> 0 | O10: =Sugar!O73 -> 0 | P10: =Sugar!P73 -> 0 | Q10: =Sugar!Q73 -> 0 | R10: =Sugar!R73 -> 0 | S10: =SUM(O10:R10) -> 0 | T10: =Sugar!T73 -> 0 | U10: =Sugar!U73 -> 0 | V10: =Sugar!V73 -> 0 | W10: =Sugar!W73 -> 0 | X10: =SUM(T10:W10) -> 0 | Y10: =Sugar!Y73 -> 0 | Z10: =Sugar!Z73 -> 0 | AA10: =Sugar!AA73 -> 0 | AB10: =Sugar!AB73 -> 0 | AC10: =SUM(Y10:AB10) -> 0
A12: # | B12: Ethanol Sale | E12: =Ethanol!E31 -> 0 | F12: =Ethanol!F31 -> 0 | G12: =Ethanol!G31 -> 2028068850 | H12: =Ethanol!H31 -> 2.1018168e+09 | I12: =SUM(E12:H12) -> 4.1298857e+09 | J12: =Ethanol!J31 -> 2.1044986e+09 | K12: =Ethanol!K31 -> 2.1045961e+09 | L12: =Ethanol!L31 -> 2.1617283e+09 | M12: =Ethanol!M31 -> 2.1638059e+09 | N12: =SUM(J12:M12) -> 8.5346288e+09 | O12: =Ethanol!O31 -> 2.1638814e+09 | P12: =Ethanol!P31 -> 2.1638841e+09 | Q12: =Ethanol!Q31 -> 2.2210129e+09 | R12: =Ethanol!R31 -> 2.2230904e+09 | S12: =SUM(O12:R12) -> 8.7718688e+09 | T12: =Ethanol!T31 -> 2.2231659e+09 | U12: =Ethanol!U31 -> 2.2231686e+09 | V12: =Ethanol!V31 -> 2.2802974e+09 | W12: =Ethanol!W31 -> 2.2823749e+09 | X12: =SUM(T12:W12) -> 9.0090068e+09 | Y12: =Ethanol!Y31 -> 2.2824504e+09 | Z12: =Ethanol!Z31 -> 2.2824531e+09 | AA12: =Ethanol!AA31 -> 2.3395819e+09 | AB12: =Ethanol!AB31 -> 2.3416594e+09 | AC12: =SUM(Y12:AB12) -> 9.2461448e+09
B13: DDGS Sale | E13: =Ethanol!E43 -> 0 | F13: =Ethanol!F43 -> 0 | G13: =Ethanol!G43 -> 3.7476595e+08 | H13: =Ethanol!H43 -> 3.7663978e+08 | I13: =SUM(E13:H13) -> 7.5140573e+08 | J13: =Ethanol!J43 -> 3.7852298e+08 | K13: =Ethanol!K43 -> 3.8041559e+08 | L13: =Ethanol!L43 -> 3.9308718e+08 | M13: =Ethanol!M43 -> 3.9505262e+08 | N13: =SUM(J13:M13) -> 1.5470784e+09 | O13: =Ethanol!O43 -> 3.9702788e+08 | P13: =Ethanol!P43 -> 3.9901302e+08 | Q13: =Ethanol!Q43 -> 4.1199461e+08 | R13: =Ethanol!R43 -> 4.1405458e+08 | S13: =SUM(O13:R13) -> 1.6220901e+09 | T13: =Ethanol!T43 -> 4.1612486e+08 | U13: =Ethanol!U43 -> 4.1820548e+08 | V13: =Ethanol!V43 -> 4.3150441e+08 | W13: =Ethanol!W43 -> 4.3366194e+08 | X13: =SUM(T13:W13) -> 1.6994967e+09 | Y13: =Ethanol!Y43 -> 4.3583025e+08 | Z13: =Ethanol!Z43 -> 4.380094e+08 | AA13: =Ethanol!AA43 -> 4.516332e+08 | AB13: =Ethanol!AB43 -> 4.5389136e+08 | AC13: =SUM(Y13:AB13) -> 1.7793642e+09
A15: # | B15: Sale of MAEQ Quota | D15: 5000000 | E15: =$D$15/4 -> 1250000 | F15: =$D$15/4 -> 1250000 | G15: =$D$15/4 -> 1250000 | H15: =$D$15/4 -> 1250000 | I15: =SUM(E15:H15) -> 5000000 | J15: =$D$15/4 -> 1250000 | K15: =$D$15/4 -> 1250000 | L15: =$D$15/4 -> 1250000 | M15: =$D$15/4 -> 1250000 | N15: =SUM(J15:M15) -> 5000000 | O15: =$D$15/4 -> 1250000 | P15: =$D$15/4 -> 1250000 | Q15: =$D$15/4 -> 1250000 | R15: =$D$15/4 -> 1250000 | S15: =SUM(O15:R15) -> 5000000 | T15: =$D$15/4 -> 1250000 | U15: =$D$15/4 -> 1250000 | V15: =$D$15/4 -> 1250000 | W15: =$D$15/4 -> 1250000 | X15: =SUM(T15:W15) -> 5000000 | Y15: =$D$15/4 -> 1250000 | Z15: =$D$15/4 -> 1250000 | AA15: =$D$15/4 -> 1250000 | AB15: =$D$15/4 -> 1250000 | AC15: =SUM(Y15:AB15) -> 5000000
A17: # | B17: Total Sales | E17: =SUM(E7:E10,E12:E13,E15:E15) -> 8.3111429e+08 | F17: =SUM(F7:F10,F12:F13,F15:F15) -> 9.8143143e+08 | G17: =SUM(G7:G10,G12:G13,G15:G15) -> 3.1098594e+09 | H17: =SUM(H7:H10,H12:H13,H15:H15) -> 3.1883638e+09 | I17: =SUM(I7:I10,I12:I13,I15) -> 8.1107688e+09 | J17: =SUM(J7:J10,J12:J13,J15:J15) -> 3.2089692e+09 | K17: =SUM(K7:K10,K12:K13,K15:K15) -> 3.1384896e+09 | L17: =SUM(L7:L10,L12:L13,L15:L15) -> 3.3325004e+09 | M17: =SUM(M7:M10,M12:M13,M15:M15) -> 3.4256172e+09 | N17: =SUM(J17:M17) -> 1.3105576e+10 | O17: =SUM(O7:O10,O12:O13,O15:O15) -> 3.3363273e+09 | P17: =SUM(P7:P10,P12:P13,P15:P15) -> 3.2608984e+09 | Q17: =SUM(Q7:Q10,Q12:Q13,Q15:Q15) -> 3.5494296e+09 | R17: =SUM(R7:R10,R12:R13,R15:R15) -> 3.6373706e+09 | S17: =SUM(O17:R17) -> 1.3784026e+10 | T17: =SUM(T7:T10,T12:T13,T15:T15) -> 3.5342393e+09 | U17: =SUM(U7:U10,U12:U13,U15:U15) -> 3.4469528e+09 | V17: =SUM(V7:V10,V12:V13,V15:V15) -> 3.7114671e+09 | W17: =SUM(W7:W10,W12:W13,W15:W15) -> 3.9300819e+09 | X17: =SUM(T17:W17) -> 1.4622741e+10 | Y17: =SUM(Y7:Y10,Y12:Y13,Y15:Y15) -> 3.8030908e+09 | Z17: =SUM(Z7:Z10,Z12:Z13,Z15:Z15) -> 3.6969167e+09 | AA17: =SUM(AA7:AA10,AA12:AA13,AA15:AA15) -> 3.8892831e+09 | AB17: =SUM(AB7:AB10,AB12:AB13,AB15:AB15) -> 4.2598209e+09 | AC17: =SUM(Y17:AB17) -> 1.5649111e+10
A19: # | B19: Operating Cost
B20: Sugar Plant
B21: =Sugar!B78 -> Raw material (sugarcane) | E21: =Sugar!E78 -> 0 | F21: =Sugar!F78 -> 0 | G21: =Sugar!G78 -> 8.316e+08 | H21: =Sugar!H78 -> 1201200000 | I21: =SUM(E21:H21) -> 2032800000 | J21: =Sugar!J78 -> 0 | K21: =Sugar!K78 -> 0 | L21: =Sugar!L78 -> 2178000000 | M21: =Sugar!M78 -> 0 | N21: =SUM(J21:M21) -> 2178000000 | O21: =Sugar!O78 -> 0 | P21: =Sugar!P78 -> 0 | Q21: =Sugar!Q78 -> 2534400000 | R21: =Sugar!R78 -> 0 | S21: =SUM(O21:R21) -> 2534400000 | T21: =Sugar!T78 -> 0 | U21: =Sugar!U78 -> 0 | V21: =Sugar!V78 -> 2985840000 | W21: =Sugar!W78 -> 0 | X21: =SUM(T21:W21) -> 2985840000 | Y21: =Sugar!Y78 -> 0 | Z21: =Sugar!Z78 -> 0 | AA21: =Sugar!AA78 -> 3511200000 | AB21: =Sugar!AB78 -> 0 | AC21: =SUM(Y21:AB21) -> 3511200000
B22: =Sugar!B79 -> Labour Cost | E22: =Sugar!E79 -> 0 | F22: =Sugar!F79 -> 0 | G22: =Sugar!G79 -> 5040000 | H22: =Sugar!H79 -> 6160000 | I22: =SUM(E22:H22) -> 11200000 | J22: =Sugar!J79 -> 0 | K22: =Sugar!K79 -> 0 | L22: =Sugar!L79 -> 5400000 | M22: =Sugar!M79 -> 7800000 | N22: =SUM(J22:M22) -> 13200000 | O22: =Sugar!O79 -> 0 | P22: =Sugar!P79 -> 0 | Q22: =Sugar!Q79 -> 6400000 | R22: =Sugar!R79 -> 8960000 | S22: =SUM(O22:R22) -> 15360000 | T22: =Sugar!T79 -> 0 | U22: =Sugar!U79 -> 0 | V22: =Sugar!V79 -> 6960000 | W22: =Sugar!W79 -> 11136000 | X22: =SUM(T22:W22) -> 18096000 | Y22: =Sugar!Y79 -> 0 | Z22: =Sugar!Z79 -> 0 | AA22: =Sugar!AA79 -> 7600000 | AB22: =Sugar!AB79 -> 13680000 | AC22: =SUM(Y22:AB22) -> 21280000
B23: =Sugar!B80 -> Power Cost | E23: =Sugar!E80 -> 0 | F23: =Sugar!F80 -> 0 | G23: =Sugar!G80 -> -51480000 | H23: =Sugar!H80 -> -62920000 | I23: =SUM(E23:H23) -> -114400000 | J23: =Sugar!J80 -> 0 | K23: =Sugar!K80 -> 0 | L23: =Sugar!L80 -> -51480000 | M23: =Sugar!M80 -> -74360000 | N23: =SUM(J23:M23) -> -125840000 | O23: =Sugar!O80 -> 0 | P23: =Sugar!P80 -> 0 | Q23: =Sugar!Q80 -> -57200000 | R23: =Sugar!R80 -> -80080000 | S23: =SUM(O23:R23) -> -137280000 | T23: =Sugar!T80 -> 0 | U23: =Sugar!U80 -> 0 | V23: =Sugar!V80 -> -57200000 | W23: =Sugar!W80 -> -91520000 | X23: =SUM(T23:W23) -> -148720000 | Y23: =Sugar!Y80 -> 0 | Z23: =Sugar!Z80 -> 0 | AA23: =Sugar!AA80 -> -57200000 | AB23: =Sugar!AB80 -> -102960000 | AC23: =SUM(Y23:AB23) -> -160160000
B24: =Sugar!B81 -> Salary for dedicated Staff | E24: =Sugar!E81 -> 4439070 | F24: =Sugar!F81 -> 4550046.8 | G24: =Sugar!G81 -> 4663797.9 | H24: =Sugar!H81 -> 4780392.9 | I24: =SUM(E24:H24) -> 18433308 | J24: =Sugar!J81 -> 4899902.7 | K24: =Sugar!K81 -> 5022400.3 | L24: =Sugar!L81 -> 5147960.3 | M24: =Sugar!M81 -> 5276659.3 | N24: =SUM(J24:M24) -> 20346922 | O24: =Sugar!O81 -> 5408575.8 | P24: =Sugar!P81 -> 5543790.1 | Q24: =Sugar!Q81 -> 5682384.9 | R24: =Sugar!R81 -> 5824444.5 | S24: =SUM(O24:R24) -> 22459195 | T24: =Sugar!T81 -> 5970055.6 | U24: =Sugar!U81 -> 6119307 | V24: =Sugar!V81 -> 6272289.7 | W24: =Sugar!W81 -> 6429096.9 | X24: =SUM(T24:W24) -> 24790749 | Y24: =Sugar!Y81 -> 6589824.4 | Z24: =Sugar!Z81 -> 6754570 | AA24: =Sugar!AA81 -> 6923434.2 | AB24: =Sugar!AB81 -> 7096520.1 | AC24: =SUM(Y24:AB24) -> 27364349
B25: Change in Inventory | E25: =-(BS!E142-BS!D142+BS!E143-BS!D143+BS!E144-BS!D144+BS!E145-BS!D145+BS!E152-BS!D152) -> 5.9444961e+08 | F25: =-(BS!F142-BS!E142+BS!F143-BS!E143+BS!F144-BS!E144+BS!F145-BS!E145+BS!F152-BS!E152) -> 781625000 | G25: =-(BS!G142-BS!F142+BS!G143-BS!F143+BS!G144-BS!F144+BS!G145-BS!F145+BS!G152-BS!F152) -> -2.712165e+08 | H25: =-(BS!H142-BS!G142+BS!H143-BS!G143+BS!H144-BS!G144+BS!H145-BS!G145+BS!H152-BS!G152) -> -6.6178514e+08 | I25: =SUM(E25:H25) -> 4.4307297e+08 | J25: =-(BS!I142-BS!H142+BS!I143-BS!H143+BS!I144-BS!H144+BS!I145-BS!H145+BS!I152-BS!H152) -> 5.8117939e+08 | K25: =-(BS!J142-BS!I142+BS!J143-BS!I143+BS!J144-BS!I144+BS!J145-BS!I145+BS!J152-BS!I152) -> 5.2306145e+08 | L25: =-(BS!K142-BS!J142+BS!K143-BS!J143+BS!K144-BS!J144+BS!K145-BS!J145+BS!K152-BS!J152) -> -1.6796226e+09 | M25: =-(BS!L142-BS!K142+BS!L143-BS!K143+BS!L144-BS!K144+BS!L145-BS!K145+BS!L152-BS!K152) -> 6.2506919e+08 | N25: =SUM(J25:M25) -> 49687454 | O25: =-(BS!M142-BS!L142+BS!M143-BS!L143+BS!M144-BS!L144+BS!M145-BS!L145+BS!M152-BS!L152) -> 5.5633566e+08 | P25: =-(BS!N142-BS!M142+BS!N143-BS!M143+BS!N144-BS!M144+BS!N145-BS!M145+BS!N152-BS!M152) -> 5.007021e+08 | Q25: =-(BS!O142-BS!N142+BS!O143-BS!N143+BS!O144-BS!N144+BS!O145-BS!N145+BS!O152-BS!N152) -> -1.9518165e+09 | R25: =-(BS!P142-BS!O142+BS!P143-BS!O143+BS!P144-BS!O144+BS!P145-BS!O145+BS!P152-BS!O152) -> 7.1721447e+08 | S25: =SUM(O25:R25) -> -1.7756424e+08 | T25: =-(BS!Q142-BS!P142+BS!Q143-BS!P143+BS!Q144-BS!P144+BS!Q145-BS!P145+BS!Q152-BS!P152) -> 6.4511779e+08 | U25: =-(BS!R142-BS!Q142+BS!R143-BS!Q143+BS!R144-BS!Q144+BS!R145-BS!Q145+BS!R152-BS!Q152) -> 5.8060601e+08 | V25: =-(BS!S142-BS!R142+BS!S143-BS!R143+BS!S144-BS!R144+BS!S145-BS!R145+BS!S152-BS!R152) -> -2.3729225e+09 | W25: =-(BS!T142-BS!S142+BS!T143-BS!S143+BS!T144-BS!S144+BS!T145-BS!S145+BS!T152-BS!S152) -> 8.6567018e+08 | X25: =SUM(T25:W25) -> -2.8152856e+08 | Y25: =-(BS!U142-BS!T142+BS!U143-BS!T143+BS!U144-BS!T144+BS!U145-BS!T145+BS!U152-BS!T152) -> 7.8588207e+08 | Z25: =-(BS!V142-BS!U142+BS!V143-BS!U143+BS!V144-BS!U144+BS!V145-BS!U145+BS!V152-BS!U152) -> 7.0729386e+08 | AA25: =-(BS!W142-BS!V142+BS!W143-BS!V143+BS!W144-BS!V144+BS!W145-BS!V145+BS!W152-BS!V152) -> -2.8563663e+09 | AB25: =-(BS!X142-BS!W142+BS!X143-BS!W143+BS!X144-BS!W144+BS!X145-BS!W145+BS!X152-BS!W152) -> 1.0548458e+09 | AC25: =SUM(Y25:AB25) -> -3.0834456e+08
B26: =Sugar!B82 -> Other Cost | E26: =Sugar!E82 -> 0 | F26: =Sugar!F82 -> 0 | G26: =Sugar!G82 -> 8820000 | H26: =Sugar!H82 -> 10780000 | I26: =SUM(E26:H26) -> 19600000 | J26: =Sugar!J82 -> 0 | K26: =Sugar!K82 -> 0 | L26: =Sugar!L82 -> 9450000 | M26: =Sugar!M82 -> 13650000 | N26: =SUM(J26:M26) -> 23100000 | O26: =Sugar!O82 -> 0 | P26: =Sugar!P82 -> 0 | Q26: =Sugar!Q82 -> 11200000 | R26: =Sugar!R82 -> 15680000 | S26: =SUM(O26:R26) -> 26880000 | T26: =Sugar!T82 -> 0 | U26: =Sugar!U82 -> 0 | V26: =Sugar!V82 -> 12180000 | W26: =Sugar!W82 -> 19488000 | X26: =SUM(T26:W26) -> 31668000 | Y26: =Sugar!Y82 -> 0 | Z26: =Sugar!Z82 -> 0 | AA26: =Sugar!AA82 -> 13300000 | AB26: =Sugar!AB82 -> 23940000 | AC26: =SUM(Y26:AB26) -> 37240000
B27: Cost of Material Consumed -Suger Plant | E27: =SUM(E21:E26) -> 5.9888868e+08 | F27: =SUM(F21:F26) -> 7.8617505e+08 | G27: =SUM(G21:G26) -> 5.274273e+08 | H27: =SUM(H21:H26) -> 4.9821525e+08 | I27: =SUM(I21:I26) -> 2.4107063e+09 | J27: =SUM(J21:J26) -> 5.8607929e+08 | K27: =SUM(K21:K26) -> 5.2808385e+08 | L27: =SUM(L21:L26) -> 4.6689538e+08 | ... AC27: =SUM(AC21:AC26) -> 3.1285798e+09
A28: # | B28: Ethanol plant
B29: =Ethanol!B47 -> Cost of Corn Purchase | E29: =Ethanol!E47 -> 0 | F29: =Ethanol!F47 -> 0 | G29: =Ethanol!G47 -> 1.9192045e+09 | H29: =Ethanol!H47 -> 1.8735092e+09 | I29: =SUM(E29:H29) -> 3.7927137e+09 | J29: =Ethanol!J47 -> 1.8735092e+09 | K29: =Ethanol!K47 -> 1.8735092e+09 | L29: =Ethanol!L47 -> 7.1413459e+09 | M29: =Ethanol!M47 -> 0 | N29: =SUM(J29:M29) -> 1.0888364e+10 | O29: =Ethanol!O47 -> 0 | P29: =Ethanol!P47 -> 0 | Q29: =Ethanol!Q47 -> 7.3369993e+09 | R29: =Ethanol!R47 -> 0 | S29: =SUM(O29:R29) -> 7.3369993e+09 | T29: =Ethanol!T47 -> 0 | U29: =Ethanol!U47 -> 0 | V29: =Ethanol!V47 -> 7.5326526e+09 | W29: =Ethanol!W47 -> 0 | X29: =SUM(T29:W29) -> 7.5326526e+09 | Y29: =Ethanol!Y47 -> 0 | Z29: =Ethanol!Z47 -> 0 | AA29: =Ethanol!AA47 -> 7.7283059e+09 | AB29: =Ethanol!AB47 -> 0 | AC29: =SUM(Y29:AB29) -> 7.7283059e+09
B30: =Ethanol!B48 -> Labour Cost | E30: =Ethanol!E48 -> 0 | F30: =Ethanol!F48 -> 0 | G30: =Ethanol!G48 -> 4569534.6 | H30: =Ethanol!H48 -> 4569534.6 | I30: =SUM(E30:H30) -> 9139069.3 | J30: =Ethanol!J48 -> 4569534.6 | K30: =Ethanol!K48 -> 4569534.6 | L30: =Ethanol!L48 -> 4698253.9 | M30: =Ethanol!M48 -> 4698253.9 | N30: =SUM(J30:M30) -> 18535577 | O30: =Ethanol!O48 -> 4698253.9 | P30: =Ethanol!P48 -> 4698253.9 | Q30: =Ethanol!Q48 -> 4826973.2 | R30: =Ethanol!R48 -> 4826973.2 | S30: =SUM(O30:R30) -> 19050454 | T30: =Ethanol!T48 -> 4826973.2 | U30: =Ethanol!U48 -> 4826973.2 | V30: =Ethanol!V48 -> 4955692.5 | W30: =Ethanol!W48 -> 4955692.5 | X30: =SUM(T30:W30) -> 19565331 | Y30: =Ethanol!Y48 -> 4955692.5 | Z30: =Ethanol!Z48 -> 4955692.5 | AA30: =Ethanol!AA48 -> 5084411.8 | AB30: =Ethanol!AB48 -> 5084411.8 | AC30: =SUM(Y30:AB30) -> 20080208
B31: =Ethanol!B49 -> Power Cost | E31: =Ethanol!E49 -> 0 | F31: =Ethanol!F49 -> 0 | G31: =Ethanol!G49 -> -28737500 | H31: =Ethanol!H49 -> -28737500 | I31: =SUM(E31:H31) -> -57475000 | J31: =Ethanol!J49 -> -28737500 | K31: =Ethanol!K49 -> -28737500 | L31: =Ethanol!L49 -> -28737500 | M31: =Ethanol!M49 -> -28737500 | N31: =SUM(J31:M31) -> -114950000 | O31: =Ethanol!O49 -> -28737500 | P31: =Ethanol!P49 -> 731600.71 | Q31: =Ethanol!Q49 -> -28737500 | R31: =Ethanol!R49 -> -28737500 | S31: =SUM(O31:R31) -> -85480899 | T31: =Ethanol!T49 -> -28737500 | U31: =Ethanol!U49 -> 22382500 | V31: =Ethanol!V49 -> -28737500 | W31: =Ethanol!W49 -> -28737500 | X31: =SUM(T31:W31) -> -63830000 | Y31: =Ethanol!Y49 -> -28737500 | Z31: =Ethanol!Z49 -> -28737500 | AA31: =Ethanol!AA49 -> -28737500 | AB31: =Ethanol!AB49 -> -28737500 | AC31: =SUM(Y31:AB31) -> -114950000
B32: =Ethanol!B50 -> Salary for dedicated Staff | E32: =Ethanol!E50 -> 3465525 | F32: =Ethanol!F50 -> 3552163.1 | G32: =Ethanol!G50 -> 4610168.8 | H32: =Ethanol!H50 -> 5139352.8 | I32: =SUM(E32:H32) -> 16767210 | J32: =Ethanol!J50 -> 5267836.6 | K32: =Ethanol!K50 -> 5399532.6 | L32: =Ethanol!L50 -> 5534520.9 | M32: =Ethanol!M50 -> 5672883.9 | N32: =SUM(J32:M32) -> 21874774 | O32: =Ethanol!O50 -> 5814706 | P32: =Ethanol!P50 -> 5960073.6 | Q32: =Ethanol!Q50 -> 6109075.5 | R32: =Ethanol!R50 -> 6261802.4 | S32: =SUM(O32:R32) -> 24145657 | T32: =Ethanol!T50 -> 6418347.4 | U32: =Ethanol!U50 -> 6578806.1 | V32: =Ethanol!V50 -> 6743276.3 | W32: =Ethanol!W50 -> 6911858.2 | X32: =SUM(T32:W32) -> 26652288 | Y32: =Ethanol!Y50 -> 7084654.6 | Z32: =Ethanol!Z50 -> 7261771 | AA32: =Ethanol!AA50 -> 7443315.3 | AB32: =Ethanol!AB50 -> 7629398.1 | AC32: =SUM(Y32:AB32) -> 29419139
B33: Change in Inventory | E33: =-(BS!E140-BS!D140+BS!E141-BS!D141+BS!E153-BS!D153) -> 0 | F33: =-(BS!F140-BS!E140+BS!F141-BS!E141+BS!F153-BS!E153) -> 0 | G33: =-(BS!G140-BS!F140+BS!G141-BS!F141+BS!G153-BS!F153) -> -70514455 | H33: =-(BS!H140-BS!G140+BS!H141-BS!G141+BS!H153-BS!G153) -> -2564162 | I33: =SUM(E33:H33) -> -73078617 | J33: =-(BS!I140-BS!H140+BS!H141-BS!H141+BS!I153-BS!H153) -> 5129467.2 | K33: =-(BS!J140-BS!I140+BS!J141-BS!I141+BS!J153-BS!I153) -> -3148.6182 | L33: =-(BS!K140-BS!J140+BS!K141-BS!J141+BS!K153-BS!J153) -> -5.0759589e+09 | M33: =-(BS!L140-BS!K140+BS!L141-BS!K141+BS!L153-BS!K153) -> 1.6913043e+09 | N33: =SUM(J33:M33) -> -3.3795282e+09 | O33: =-(BS!M140-BS!L140+BS!L141-BS!L141+BS!M153-BS!L153) -> 1.6910748e+09 | P33: =-(BS!N140-BS!M140+BS!N141-BS!M141+BS!N153-BS!M153) -> 1.6913713e+09 | Q33: =-(BS!O140-BS!N140+BS!O141-BS!N141+BS!O153-BS!N153) -> -5.2149834e+09 | R33: =-(BS!P140-BS!O140+BS!P141-BS!O141+BS!P153-BS!O153) -> 1.737643e+09 | S33: =SUM(O33:R33) -> -94894246 | T33: =-(BS!Q140-BS!P140+BS!P141-BS!P141+BS!Q153-BS!P153) -> 1.7374922e+09 | U33: =-(BS!R140-BS!Q140+BS!R141-BS!Q141+BS!R153-BS!Q153) -> 1.7377103e+09 | V33: =-(BS!S140-BS!R140+BS!S141-BS!R141+BS!S153-BS!R153) -> -5.4729424e+09 | W33: =-(BS!T140-BS!S140+BS!T141-BS!S141+BS!T153-BS!S153) -> 1.8236273e+09 | X33: =SUM(T33:W33) -> -1.7411264e+08 | Y33: =-(BS!U140-BS!T140+BS!T141-BS!T141+BS!U153-BS!T153) -> 1.8241576e+09 | Z33: =-(BS!V140-BS!U140+BS!V141-BS!U141+BS!V153-BS!U153) -> 1.8236947e+09 | AA33: =-(BS!W140-BS!V140+BS!W141-BS!V141+BS!W153-BS!V153) -> -5.6150368e+09 | AB33: =-(BS!X140-BS!W140+BS!X141-BS!W141+BS!X153-BS!W153) -> 1.8709964e+09 | AC33: =SUM(Y33:AB33) -> -96188114
B34: =Ethanol!B51 -> Other Cost | E34: =Ethanol!E51 -> 0 | F34: =Ethanol!F51 -> 0 | G34: =Ethanol!G51 -> 58575000 | H34: =Ethanol!H51 -> 58575000 | I34: =SUM(E34:H34) -> 117150000 | J34: =Ethanol!J51 -> 58575000 | K34: =Ethanol!K51 -> 58575000 | L34: =Ethanol!L51 -> 60225000 | M34: =Ethanol!M51 -> 60225000 | N34: =SUM(J34:M34) -> 237600000 | O34: =Ethanol!O51 -> 60225000 | P34: =Ethanol!P51 -> 60225000 | Q34: =Ethanol!Q51 -> 61875000 | R34: =Ethanol!R51 -> 61875000 | S34: =SUM(O34:R34) -> 244200000 | T34: =Ethanol!T51 -> 61875000 | U34: =Ethanol!U51 -> 61875000 | V34: =Ethanol!V51 -> 63525000 | W34: =Ethanol!W51 -> 63525000 | X34: =SUM(T34:W34) -> 250800000 | Y34: =Ethanol!Y51 -> 63525000 | Z34: =Ethanol!Z51 -> 63525000 | AA34: =Ethanol!AA51 -> 65175000 | AB34: =Ethanol!AB51 -> 65175000 | AC34: =SUM(Y34:AB34) -> 257400000
B35: Cost of Material Consumed for Ethanol Plant | E35: =SUM(E29:E34) -> 3465525 | F35: =SUM(F29:F34) -> 3552163.1 | G35: =SUM(G29:G34) -> 1.8877073e+09 | H35: =SUM(H29:H34) -> 1.9104914e+09 | I35: =SUM(I29:I34) -> 3.8052164e+09 | J35: =SUM(J29:J34) -> 1.9183135e+09 | K35: =SUM(K29:K34) -> 1.9133126e+09 | L35: =SUM(L29:L34) -> 2.1071073e+09 | ... AC35: =SUM(AC29:AC34) -> 7.8240671e+09
B37: Salaries Corporate Employees | C37: 0.03 | E37: =Employee!E28 -> 6748395 | F37: =Employee!F28 -> 6917104.9 | G37: =Employee!G28 -> 7090032.5 | H37: =Employee!H28 -> 7267283.3 | I37: =SUM(E37:H37) -> 28022816 | J37: =Employee!J28 -> 7448965.4 | K37: =Employee!K28 -> 7635189.5 | L37: =Employee!L28 -> 7826069.3 | M37: =Employee!M28 -> 8021721 | N37: =SUM(J37:M37) -> 30931945 | O37: =Employee!O28 -> 8222264 | P37: =Employee!P28 -> 8427820.6 | Q37: =Employee!Q28 -> 8638516.1 | R37: =Employee!R28 -> 8854479 | S37: =SUM(O37:R37) -> 34143080 | T37: =Employee!T28 -> 9075841 | U37: =Employee!U28 -> 9302737 | V37: =Employee!V28 -> 9535305.5 | W37: =Employee!W28 -> 9773688.1 | X37: =SUM(T37:W37) -> 37687572 | Y37: =Employee!Y28 -> 10018030 | Z37: =Employee!Z28 -> 10268481 | AA37: =Employee!AA28 -> 10525193 | AB37: =Employee!AB28 -> 10788323 | AC37: =SUM(Y37:AB37) -> 41600027
B38: Research Expenses | C38: 0.1 | D38: Increase | E38: 1000000 | F38: =E38*(1+$C38/4) -> 1025000 | G38: =F38*(1+$C38/4) -> 1050625 | H38: =G38*(1+$C38/4) -> 1076890.6 | I38: =SUM(E38:H38) -> 4152515.6 | J38: =H38*(1+$C38/4) -> 1103812.9 | K38: =J38*(1+$C38/4) -> 1131408.2 | L38: =K38*(1+$C38/4) -> 1159693.4 | M38: =L38*(1+$C38/4) -> 1188685.8 | N38: =SUM(J38:M38) -> 4583600.3 | O38: =M38*(1+$C38/4) -> 1218402.9 | P38: =O38*(1+$C38/4) -> 1248863 | Q38: =P38*(1+$C38/4) -> 1280084.5 | R38: =Q38*(1+$C38/4) -> 1312086.7 | S38: =SUM(O38:R38) -> 5059437.1 | T38: =R38*(1+$C38/4) -> 1344888.8 | U38: =T38*(1+$C38/4) -> 1378511 | V38: =U38*(1+$C38/4) -> 1412973.8 | W38: =V38*(1+$C38/4) -> 1448298.2 | X38: =SUM(T38:W38) -> 5584671.9 | Y38: =W38*(1+$C38/4) -> 1484505.6 | Z38: =Y38*(1+$C38/4) -> 1521618.3 | AA38: =Z38*(1+$C38/4) -> 1559658.7 | AB38: =AA38*(1+$C38/4) -> 1598650.2 | AC38: =SUM(Y38:AB38) -> 6164432.8
B39: Misc Expenses | C39: 0.02 | D39: Increase | E39: 5000000 | F39: =E39*(1+$C$39) -> 5100000 | G39: =F39*(1+$C$39) -> 5202000 | H39: =G39*(1+$C$39) -> 5306040 | I39: =SUM(E39:H39) -> 20608040 | J39: =H39*(1+$C$39) -> 5412160.8 | K39: =J39*(1+$C$39) -> 5520404 | L39: =K39*(1+$C$39) -> 5630812.1 | M39: =L39*(1+$C$39) -> 5743428.3 | N39: =SUM(J39:M39) -> 22306805 | O39: =M39*(1+$C$39) -> 5858296.9 | P39: =O39*(1+$C$39) -> 5975462.8 | Q39: =P39*(1+$C$39) -> 6094972.1 | R39: =Q39*(1+$C$39) -> 6216871.5 | S39: =SUM(O39:R39) -> 24145603 | T39: =R39*(1+$C$39) -> 6341209 | U39: =T39*(1+$C$39) -> 6468033.2 | V39: =U39*(1+$C$39) -> 6597393.8 | W39: =V39*(1+$C$39) -> 6729341.7 | X39: =SUM(T39:W39) -> 26135978 | Y39: =W39*(1+$C$39) -> 6863928.5 | Z39: =Y39*(1+$C$39) -> 7001207.1 | AA39: =Z39*(1+$C$39) -> 7141231.2 | AB39: =AA39*(1+$C$39) -> 7284055.9 | AC39: =SUM(Y39:AB39) -> 28290423
B40: Sales and Logestics | C40: 0.03 | D40: On Ethanol | E40: =$C40*E12 -> 0 | F40: =$C40*F12 -> 0 | G40: =$C40*G12 -> 60842066 | H40: =$C40*H12 -> 63054504 | I40: =SUM(E40:H40) -> 1.2389657e+08 | J40: =$C40*J12 -> 63134957 | K40: =$C40*K12 -> 63137882 | L40: =$C40*L12 -> 64851849 | M40: =$C40*M12 -> 64914176 | N40: =SUM(J40:M40) -> 2.5603886e+08 | O40: =$C40*O12 -> 64916442 | P40: =$C40*P12 -> 64916524 | Q40: =$C40*Q12 -> 66630388 | R40: =$C40*R12 -> 66692711 | S40: =SUM(O40:R40) -> 2.6315607e+08 | T40: =$C40*T12 -> 66694977 | U40: =$C40*U12 -> 66695059 | V40: =$C40*V12 -> 68408923 | W40: =$C40*W12 -> 68471246 | X40: =SUM(T40:W40) -> 2.7027021e+08 | Y40: =$C40*Y12 -> 68473512 | Z40: =$C40*Z12 -> 68473594 | AA40: =$C40*AA12 -> 70187458 | AB40: =$C40*AB12 -> 70249781 | AC40: =SUM(Y40:AB40) -> 2.7738435e+08
A42: # | B42: Total Cost | E42: =E27+E35+SUM(E37:E40) -> 6.151026e+08 | F42: =F27+F35+SUM(F37:F40) -> 8.0276931e+08 | G42: =G27+G35+SUM(G37:G40) -> 2.4893193e+09 | H42: =H27+H35+SUM(H37:H40) -> 2.4854114e+09 | I42: =I27+I35+SUM(I37:I40) -> 6.3926026e+09 | J42: =J27+J35+SUM(J37:J40) -> 2.5814927e+09 | K42: =K27+K35+SUM(K37:K40) -> 2.5188214e+09 | L42: =L27+L35+SUM(L37:L40) -> 2.6534711e+09 | ... AC42: =AC27+AC35+SUM(AC37:AC40) -> 1.1306086e+10
A44: # | B44: EBITDA | E44: =E17-E42 -> 2.1601169e+08 | F44: =F17-F42 -> 1.7866211e+08 | G44: =G17-G42 -> 6.2054006e+08 | H44: =H17-H42 -> 7.0295237e+08 | I44: =SUM(E44:H44) -> 1.7181662e+09 | J44: =J17-J42 -> 6.2747651e+08 | K44: =K17-K42 -> 6.1966824e+08 | L44: =L17-L42 -> 6.7902929e+08 | M44: =M17-M42 -> 1.0351504e+09 | N44: =SUM(J44:M44) -> 2.9613244e+09 | O44: =O17-O42 -> 9.6129242e+08 | P44: =P17-P42 -> 9.1109761e+08 | Q44: =Q17-Q42 -> 7.520303e+08 | R44: =R17-R42 -> 1.1048263e+09 | S44: =SUM(O44:R44) -> 3.7292467e+09 | T44: =T17-T42 -> 1.0178195e+09 | U44: =U17-U42 -> 9.430096e+08 | V44: =V17-V42 -> 9.3818604e+08 | W44: =W17-W42 -> 1.1621738e+09 | X44: =SUM(T44:W44) -> 4.0611889e+09 | Y44: =Y17-Y42 -> 1.0527935e+09 | Z44: =Z17-Z42 -> 1.0249036e+09 | AA44: =AA17-AA42 -> 1.0121781e+09 | AB44: =AB17-AB42 -> 1.25315e+09 | AC44: =SUM(Y44:AB44) -> 4.3430253e+09
B46: Less: Depreciation | E46: =-(BS!E162+BS!E168) -> 45302310 | F46: =-(BS!F162+BS!F168) -> 43603473 | G46: =-(BS!G162+BS!G168) -> 1.1616368e+08 | H46: =-(BS!H162+BS!H168) -> 1.1180755e+08 | I46: =SUM(E46:H46) -> 3.1687701e+08 | J46: =-(BS!I162+BS!I168) -> 1.0761476e+08 | K46: =-(BS!J162+BS!J168) -> 1.0357921e+08 | L46: =-(BS!K162+BS!K168) -> 99694990 | M46: =-(BS!L162+BS!L168) -> 95956427 | N46: =SUM(J46:M46) -> 4.0684539e+08 | O46: =-(BS!M162+BS!M168) -> 92358061 | P46: =-(BS!N162+BS!N168) -> 88894634 | Q46: =-(BS!O162+BS!O168) -> 85561085 | R46: =-(BS!P162+BS!P168) -> 82352545 | S46: =SUM(O46:R46) -> 3.4916633e+08 | T46: =-(BS!Q162+BS!Q168) -> 79264324 | U46: =-(BS!R162+BS!R168) -> 76291912 | V46: =-(BS!S162+BS!S168) -> 73430965 | W46: =-(BS!T162+BS!T168) -> 70677304 | X46: =SUM(T46:W46) -> 2.9966451e+08 | Y46: =-(BS!U162+BS!U168) -> 68026905 | Z46: =-(BS!V162+BS!V168) -> 65475896 | AA46: =-(BS!W162+BS!W168) -> 63020550 | AB46: =-(BS!X162+BS!X168) -> 60657280 | AC46: =SUM(Y46:AB46) -> 2.5718063e+08
B47: less: interest | E47: =BS!E175 -> 93282407 | F47: =BS!F175 -> 98489477 | G47: =BS!G175 -> 95443826 | H47: =BS!H175 -> 92434099 | I47: =SUM(E47:H47) -> 3.7964981e+08 | J47: =BS!I175 -> 89457413 | K47: =BS!J175 -> 86510959 | L47: =BS!K175 -> 83592007 | M47: =BS!L175 -> 21408071 | N47: =SUM(J47:M47) -> 2.8096845e+08 | O47: =BS!M175 -> 20783039 | P47: =BS!N175 -> 20148630 | Q47: =BS!O175 -> 19504706 | R47: =BS!P175 -> 18851123 | S47: =SUM(O47:R47) -> 79287497 | T47: =BS!Q175 -> 18187736 | U47: =BS!R175 -> 17514398 | V47: =BS!S175 -> 16830960 | W47: =BS!T175 -> 16137270 | X47: =SUM(T47:W47) -> 68670364 | Y47: =BS!U175 -> 15433176 | Z47: =BS!V175 -> 14718519 | AA47: =BS!W175 -> 13993143 | AB47: =BS!X175 -> 13256887 | AC47: =SUM(Y47:AB47) -> 57401725
A49: # | B49: PBT | E49: =E44-E47-E46 -> 77426969 | F49: =F44-F47-F46 -> 36569164 | G49: =G44-G47-G46 -> 4.0893255e+08 | H49: =H44-H47-H46 -> 4.9871072e+08 | I49: =SUM(E49:H49) -> 1.0216394e+09 | J49: =J44-J47-J46 -> 4.3040433e+08 | K49: =K44-K47-K46 -> 4.2957807e+08 | L49: =L44-L47-L46 -> 4.9574229e+08 | M49: =M44-M47-M46 -> 9.1778587e+08 | N49: =SUM(J49:M49) -> 2.2735106e+09 | O49: =O44-O47-O46 -> 8.4815132e+08 | P49: =P44-P47-P46 -> 8.0205435e+08 | Q49: =Q44-Q47-Q46 -> 6.4696451e+08 | R49: =R44-R47-R46 -> 1.0036226e+09 | S49: =SUM(O49:R49) -> 3.3007928e+09 | T49: =T44-T47-T46 -> 9.2036746e+08 | U49: =U44-U47-U46 -> 8.4920329e+08 | V49: =V44-V47-V46 -> 8.4792411e+08 | W49: =W44-W47-W46 -> 1.0753592e+09 | X49: =SUM(T49:W49) -> 3.692854e+09 | Y49: =Y44-Y47-Y46 -> 9.6933345e+08 | Z49: =Z44-Z47-Z46 -> 9.4470923e+08 | AA49: =AA44-AA47-AA46 -> 9.3516445e+08 | AB49: =AB44-AB47-AB46 -> 1.1792358e+09 | AC49: =SUM(Y49:AB49) -> 4.0284429e+09
B51: less: tax | C51: 0.2517 | E51: =E49*$C$51 -> 19488368 | F51: =F49*$C$51 -> 9204458.6 | G51: =G49*$C$51 -> 1.0292832e+08 | H51: =H49*$C$51 -> 1.2552549e+08 | I51: =I49*($C51) -> 2.5714664e+08 | J51: =J49*$C$51 -> 1.0833277e+08 | K51: =K49*$C$51 -> 1.081248e+08 | L51: =L49*$C$51 -> 1.2477834e+08 | M51: =M49*$C$51 -> 2.310067e+08 | N51: =SUM(J51:M51) -> 5.7224261e+08 | O51: =O49*$C$51 -> 2.1347969e+08 | P51: =P49*$C$51 -> 2.0187708e+08 | Q51: =Q49*$C$51 -> 1.6284097e+08 | R51: =R49*$C$51 -> 2.5261182e+08 | S51: =SUM(O51:R51) -> 8.3080956e+08 | T51: =T49*$C$51 -> 2.3165649e+08 | U51: =U49*$C$51 -> 2.1374447e+08 | V51: =V49*$C$51 -> 2.134225e+08 | W51: =W49*$C$51 -> 2.7066791e+08 | X51: =SUM(T51:W51) -> 9.2949136e+08 | Y51: =Y49*$C$51 -> 2.4398123e+08 | Z51: =Z49*$C$51 -> 2.3778331e+08 | AA51: =AA49*$C$51 -> 2.3538089e+08 | AB51: =AB49*$C$51 -> 2.9681365e+08 | AC51: =SUM(Y51:AB51) -> 1.0139591e+09
...

Sheet BS
C1: =C11/9 -> 1.7838131e+08 | E1: =C1/39000 -> 4573.8796 | F1: =E1/10.75% -> 42547.718
B3: No..of days of operation(days) | C3: 0 | E3: =300/4 -> 75 | F3: =300/4 -> 75 | G3: =300/4 -> 75 | H3: =300/4 -> 75 | I3: =300/4 -> 75 | J3: =300/4 -> 75 | K3: =300/4 -> 75 | L3: =300/4 -> 75 | ... X3: =300/4 -> 75
B4: Column counter | C4: 0 | E4: 1 | F4: =E4+1 -> 2 | G4: =F4+1 -> 3 | H4: =G4+1 -> 4 | I4: =H4+1 -> 5 | J4: =I4+1 -> 6 | K4: =J4+1 -> 7 | L4: =K4+1 -> 8 | M4: =L4+1 -> 9 | ... X4: =W4+1 -> 20
B5: Particulars | C5: 45747 | E5: 45838 | F5: =EOMONTH(E5,3) -> 45930 | G5: =EOMONTH(F5,3) -> 46022 | H5: =EDATE(G5,3) -> 46112 | I5: =EOMONTH(H5,3) -> 46203 | J5: =EOMONTH(I5,3) -> 46295 | K5: =EOMONTH(J5,3) -> 46387 | L5: =EOMONTH(K5,3) -> 46477 | M5: =EOMONTH(L5,3) -> 46568 | N5: =EOMONTH(M5,3) -> 46660 | O5: =EOMONTH(N5,3) -> 46752 | P5: =EOMONTH(O5,3) -> 46843 | ... X5: =EOMONTH(W5,3) -> 47573
A7: # | B7: Current Assets
B8: Cash and bank balances | C8: 24920421 | E8: =CFS!D26 -> 1.0252677e+09 | F8: =CFS!E26 -> 1.5289637e+09 | G8: =CFS!F26 -> 1.116618e+09 | H8: =CFS!G26 -> 1.0132796e+09 | I8: =CFS!I26 -> 1.733431e+09 | J8: =CFS!J26 -> 2.6026177e+09 | K8: =CFS!K26 -> -4.9706501e+09 | L8: =CFS!L26 -> -1.9149498e+09 | M8: =CFS!N26 -> 1.0184113e+09 | N8: =CFS!O26 -> 3.8574247e+09 | O8: =CFS!P26 -> -2.8027944e+09 | P8: =CFS!Q26 -> 4.3952753e+08 | Q8: =CFS!S26 -> 3.5465734e+09 | R8: =CFS!T26 -> 6.5320042e+09 | S8: =CFS!U26 -> -6.7140671e+08 | T8: =CFS!V26 -> 2.8431779e+09 | U8: =CFS!X26 -> 6.0635362e+09 | V8: =CFS!Y26 -> 9.3199294e+09 | W8: =CFS!Z26 -> 1.5401745e+09 | X8: =CFS!AA26 -> 5.3534843e+09
B9: Investments (other than long term invt.) | C9: 0 | E9: =C9 -> 0 | F9: =E9 -> 0 | G9: =F9 -> 0 | H9: =G9 -> 0 | I9: =H9 -> 0 | J9: =I9 -> 0 | K9: =J9 -> 0 | L9: =K9 -> 0 | M9: =L9 -> 0 | ... X9: =W9 -> 0
B10: Trade Receiveables | C10: 1.7286956e+08 | E10: =E70 -> 1.3831071e+08 | F10: =F70 -> 1.6336357e+08 | G10: =G70 -> 7.1600785e+08 | H10: =H70 -> 6.2762015e+08 | I10: =I70 -> 6.4545912e+08 | J10: =J70 -> 6.4482928e+08 | K10: =K70 -> 6.4622925e+08 | L10: =L70 -> 6.4788465e+08 | ... X10: =X70 -> 8.4943783e+08
B11: Inventories | C11: 1.6054318e+09 | E11: =E146+E155 -> 1.0109821e+09 | F11: =F146+F155 -> 2.2935714e+08 | G11: =G146+G155 -> 5.710881e+08 | H11: =H146+H155 -> 1.2354374e+09 | I11: =I146+I155 -> 6.4912854e+08 | J11: =J146+J155 -> 1.2607024e+08 | K11: =K146+K155 -> 6.8816517e+09 | L11: =L146+L155 -> 4.5652782e+09 | ... X11: =X146+X155 -> 5.6979106e+09
B12: Short Term Loans & Advances | C12: 88315120 | E12: =C12 -> 88315120 | F12: =E12 -> 88315120 | G12: =F12 -> 88315120 | H12: =G12 -> 88315120 | I12: =H12 -> 88315120 | J12: =I12 -> 88315120 | K12: =J12 -> 88315120 | L12: =K12 -> 88315120 | M12: =L12 -> 88315120 | ... X12: =W12 -> 88315120
B13: Other Current Assets (including TDS & Adv Tax) | C13: 1.6642346e+08 | E13: =C13 -> 1.6642346e+08 | F13: =E13 -> 1.6642346e+08 | G13: =F13 -> 1.6642346e+08 | H13: =G13 -> 1.6642346e+08 | I13: =H13 -> 1.6642346e+08 | J13: =I13 -> 1.6642346e+08 | K13: =J13 -> 1.6642346e+08 | L13: =K13 -> 1.6642346e+08 | M13: =L13 -> 1.6642346e+08 | ... X13: =W13 -> 1.6642346e+08
A15: # | B15: Non-Current Assets
B16: Progress Ethanol Plant | C16: 1.7285424e+09 | E16: =E169 -> 1.7285424e+09 | F16: =F169 -> 1.9785424e+09 | G16: =G169 -> 1.9043471e+09 | H16: =H169 -> 1.8329341e+09 | I16: =I169 -> 1.7641991e+09 | J16: =J169 -> 1.6980416e+09 | K16: =K169 -> 1.634365e+09 | L16: =L169 -> 1.5730763e+09 | ... X16: =X169 -> 9.9439438e+08
B17: Suger and Power Plant | C17: 1.2080616e+09 | E17: =E163 -> 1.1627593e+09 | F17: =F163 -> 1.1191558e+09 | G17: =G163 -> 1.0771875e+09 | H17: =H163 -> 1.0367929e+09 | I17: =I163 -> 9.979132e+08 | J17: =J163 -> 9.6049146e+08 | K17: =K163 -> 9.2447303e+08 | L17: =L163 -> 8.8980529e+08 | ... X17: =X163 -> 5.624758e+08
B18: Non-current investments | C18: 59760000 | E18: =C18 -> 59760000 | F18: =E18 -> 59760000 | G18: =F18 -> 59760000 | H18: =G18 -> 59760000 | I18: =H18 -> 59760000 | J18: =I18 -> 59760000 | K18: =J18 -> 59760000 | L18: =K18 -> 59760000 | M18: =L18 -> 59760000 | ... X18: =W18 -> 59760000
B19: Long term loans and advances | C19: 128709301 | E19: =C19 -> 128709301 | F19: =E19 -> 128709301 | G19: =F19 -> 128709301 | H19: =G19 -> 128709301 | I19: =H19 -> 128709301 | J19: =I19 -> 128709301 | K19: =J19 -> 128709301 | L19: =K19 -> 128709301 | M19: =L19 -> 128709301 | ... X19: =W19 -> 128709301
B20: Other Non-Current assets | C20: 1.2756287e+08 | E20: =C20 -> 1.2756287e+08 | F20: =E20 -> 1.2756287e+08 | G20: =F20 -> 1.2756287e+08 | H20: =G20 -> 1.2756287e+08 | I20: =H20 -> 1.2756287e+08 | J20: =I20 -> 1.2756287e+08 | K20: =J20 -> 1.2756287e+08 | L20: =K20 -> 1.2756287e+08 | M20: =L20 -> 1.2756287e+08 | ... X20: =W20 -> 1.2756287e+08
A22: # | B22: Total Assets | C22: =(SUM(C8:C13,C16:C20)) -> 5.3105965e+09 | E22: =SUM(E8:E13,E16:E20) -> 5.6366331e+09 | F22: =SUM(F8:F13,F16:F20) -> 5.5901535e+09 | G22: =SUM(G8:G13,G16:G20) -> 5.9560192e+09 | H22: =SUM(H8:H13,H16:H20) -> 6.316835e+09 | I22: =SUM(I8:I13,I16:I20) -> 6.3609017e+09 | J22: =SUM(J8:J13,J16:J20) -> 6.602821e+09 | K22: =SUM(K8:K14,K16:K20) -> 5.6868397e+09 | L22: =SUM(L8:L13,L16:L20) -> 6.3318654e+09 | M22: =SUM(M8:M13,M16:M20) -> 6.9245308e+09 | N22: =SUM(N8:N13,N16:N20) -> 7.4817829e+09 | O22: =SUM(O8:O13,O16:O20) -> 7.9221661e+09 | P22: =SUM(P8:P13,P16:P20) -> 8.6288779e+09 | Q22: =SUM(Q8:Q13,Q16:Q20) -> 9.2729706e+09 | R22: =SUM(R8:R13,R16:R20) -> 9.8628704e+09 | S22: =SUM(S8:S13,S16:S20) -> 1.0450997e+10 | ... X22: =SUM(X8:X13,X16:X20) -> 1.4028474e+10
A24: # | B24: Liabilties
B25: Short-term borrowings | C25: 9.5897433e+08 | H25: =C25 -> 9.5897433e+08 | L25: =H25 -> 9.5897433e+08 | P25: =L25 -> 9.5897433e+08 | T25: =P25 -> 9.5897433e+08 | X25: =T25 -> 9.5897433e+08
B26: Accounts payables | C26: 6.8151108e+08 | E26: =E$124 -> 1009385.8 | F26: =F$124 -> 1034620.5 | G26: =G$124 -> 1.3614197e+08 | H26: =H$124 -> 2.0042119e+08 | I26: =I$124 -> 495275.27 | J26: =J$124 -> 498099.64 | K26: =K$124 -> 643063.72 | L26: =L$124 -> 558475.52 | ... X26: =X$124 -> 900337.73
B27: Other current liabilities | C27: 99667052 | E27: =C27 -> 99667052 | F27: =E27 -> 99667052 | G27: =F27 -> 99667052 | H27: =G27 -> 99667052 | I27: =H27 -> 99667052 | J27: =I27 -> 99667052 | K27: =J27 -> 99667052 | L27: =K27 -> 99667052 | M27: =L27 -> 99667052 | ... X27: =W27 -> 99667052
B28: Short-Term Provisions | C28: 1.816263e+08 | E28: =C28 -> 1.816263e+08 | F28: =E28 -> 1.816263e+08 | G28: =F28 -> 1.816263e+08 | H28: =G28 -> 1.816263e+08 | I28: =H28 -> 1.816263e+08 | J28: =I28 -> 1.816263e+08 | K28: =J28 -> 1.816263e+08 | L28: =K28 -> 1.816263e+08 | M28: =L28 -> 1.816263e+08 | ... X28: =W28 -> 1.816263e+08
A30: # | B30: Non-Current liabilities
B31: Long term Debt obligations | C31: =2149075099.33 -> 2.1490751e+09 | E31: =E177 -> 3.0976747e+09 | F31: =F177 -> 3.0238052e+09 | G31: =G177 -> 2.9485594e+09 | H31: =H177 -> 2.8719107e+09 | I31: =I177 -> 2.7938318e+09 | J31: =J177 -> 2.714295e+09 | K31: =K177 -> 1.4272048e+09 | L31: =L177 -> 1.3855359e+09 | ... X31: =X177 -> 8.3397241e+08
B32: Deferred Tax Liability | C32: 9892721.3 | E32: =C32 -> 9892721.3 | F32: =E32 -> 9892721.3 | G32: =F32 -> 9892721.3 | H32: =G32 -> 9892721.3 | I32: =H32 -> 9892721.3 | J32: =I32 -> 9892721.3 | K32: =J32 -> 9892721.3 | L32: =K32 -> 9892721.3 | M32: =L32 -> 9892721.3 | ... X32: =W32 -> 9892721.3
A34: # | B34: Total Liabilities | C34: =SUM(C25:C32) -> 4.0807466e+09 | E34: =SUM(E25:E32) -> 3.3898702e+09 | F34: =SUM(F25:F32) -> 3.3160259e+09 | G34: =SUM(G25:G32) -> 3.3758874e+09 | H34: =SUM(H25:H32) -> 4.3224922e+09 | I34: =SUM(I25:I32) -> 3.0855131e+09 | J34: =SUM(J25:J32) -> 3.0059791e+09 | K34: =SUM(K25:K32) -> 1.7190339e+09 | L34: =SUM(L25:L32) -> 2.6362548e+09 | ... X34: =SUM(X25:X32) -> 2.0850331e+09
B36: Equity
B37: Share Capital | C37: 57179000 | E37: =C37 -> 57179000 | F37: =E37 -> 57179000 | G37: =F37 -> 57179000 | H37: =G37 -> 57179000 | I37: =H37 -> 57179000 | J37: =I37 -> 57179000 | K37: =J37 -> 57179000 | L37: =K37 -> 57179000 | M37: =L37 -> 57179000 | ... X37: =W37 -> 57179000
B38: General Reserve | C38: 1.1568989e+09 | E38: =C38+PL!E53 -> 1.2148375e+09 | F38: =E38+PL!F53 -> 1.2422022e+09 | G38: =F38+PL!G53 -> 1.5482064e+09 | H38: =G38+PL!H53 -> 1.9213917e+09 | I38: =H38+PL!J53 -> 2.2434632e+09 | J38: =I38+PL!K53 -> 2.5649165e+09 | K38: =J38+PL!L53 -> 2.9358805e+09 | L38: =K38+PL!M53 -> 3.6226596e+09 | M38: =L38+PL!O53 -> 4.2573313e+09 | N38: =M38+PL!P53 -> 4.8575085e+09 | O38: =N38+PL!Q53 -> 5.3416321e+09 | P38: =O38+PL!R53 -> 6.0926429e+09 | Q38: =P38+PL!T53 -> 6.7813539e+09 | R38: =Q38+PL!U53 -> 7.4168127e+09 | S38: =R38+PL!V53 -> 8.0513143e+09 | T38: =S38+PL!W53 -> 8.8560056e+09 | U38: =T38+PL!Y53 -> 9.5813578e+09 | V38: =U38+PL!Z53 -> 1.0288284e+10 | W38: =V38+PL!AA53 -> 1.0988067e+10 | X38: =W38+PL!AB53 -> 1.1870489e+10
B39: Share application money pending allotment | C39: 15772050 | E39: =C39 -> 15772050 | F39: =E39 -> 15772050 | G39: =F39 -> 15772050 | H39: =G39 -> 15772050 | I39: =H39 -> 15772050 | J39: =I39 -> 15772050 | K39: =J39 -> 15772050 | L39: =K39 -> 15772050 | M39: =L39 -> 15772050 | ... X39: =W39 -> 15772050
A41: # | B41: Total Equity | C41: =SUM(C37:C39) -> 1.22985e+09 | E41: =SUM(E37:E39) -> 1.2877886e+09 | F41: =SUM(F37:F39) -> 1.3151533e+09 | G41: =SUM(G37:G39) -> 1.6211575e+09 | H41: =SUM(H37:H39) -> 1.9943427e+09 | I41: =SUM(I37:I39) -> 2.3164143e+09 | J41: =SUM(J37:J39) -> 2.6378675e+09 | K41: =SUM(K37:K39) -> 3.0088315e+09 | L41: =SUM(L37:L39) -> 3.6956107e+09 | ... X41: =SUM(X37:X39) -> 1.194344e+10
B43: Total Equity and Liability | C43: =SUM(C34,C41) -> 5.3105965e+09 | E43: =SUM(E34,E41) -> 4.6776587e+09 | F43: =SUM(F34,F41) -> 4.6311791e+09 | G43: =SUM(G34,G41) -> 4.9970449e+09 | H43: =SUM(H34,H41) -> 6.316835e+09 | I43: =SUM(I34,I41) -> 5.4019274e+09 | J43: =SUM(J34,J41) -> 5.6438467e+09 | K43: =SUM(K34,K41) -> 4.7278654e+09 | L43: =SUM(L34,L41) -> 6.3318654e+09 | ... X43: =SUM(X34,X41) -> 1.4028474e+10
B44: check sum | C44: =C22-C43 -> 0 | E44: =E22-E43 -> 9.5897433e+08 | F44: =F22-F43 -> 9.5897433e+08 | G44: =G22-G43 -> 9.5897433e+08 | H44: =H22-H43 -> 0 | I44: =I22-I43 -> 9.5897433e+08 | J44: =J22-J43 -> 9.5897433e+08 | K44: =K22-K43 -> 9.5897433e+08 | L44: =L22-L43 -> 0 | ... X44: =X22-X43 -> 0
B47: CA | C47: =SUM(C9:C13) -> 2.0330399e+09 | E47: =SUM(E9:E13) -> 1.4040314e+09 | F47: =SUM(F9:F13) -> 6.4745929e+08 | G47: =SUM(G9:G13) -> 1.5418345e+09 | H47: =SUM(H9:H13) -> 2.1177961e+09 | I47: =SUM(I9:I13) -> 1.5493262e+09 | J47: =SUM(J9:J13) -> 1.0256381e+09 | K47: =SUM(K9:K13) -> 7.7826195e+09 | L47: =SUM(L9:L13) -> 5.4679014e+09 | ... X47: =SUM(X9:X13) -> 6.802087e+09
B48: CL | C48: =SUM(C26:C28) -> 9.6280443e+08 | E48: =SUM(E26:E28) -> 2.8230273e+08 | F48: =SUM(F26:F28) -> 2.8232797e+08 | G48: =SUM(G26:G28) -> 4.1743532e+08 | H48: =SUM(H26:H28) -> 4.8171453e+08 | I48: =SUM(I26:I28) -> 2.8178862e+08 | J48: =SUM(J26:J28) -> 2.8179145e+08 | K48: =SUM(K26:K28) -> 2.8193641e+08 | L48: =SUM(L26:L28) -> 2.8185182e+08 | ... X48: =SUM(X26:X28) -> 2.8219368e+08
B49: NWC | C49: =C47-C48 -> 1.0702355e+09 | E49: =E47-E48 -> 1.1217287e+09 | F49: =F47-F48 -> 3.6513132e+08 | G49: =G47-G48 -> 1.1243992e+09 | H49: =H47-H48 -> 1.6360816e+09 | I49: =I47-I48 -> 1.2675376e+09 | J49: =J47-J48 -> 7.4384665e+08 | K49: =K47-K48 -> 7.5006831e+09 | L49: =L47-L48 -> 5.1860496e+09 | ... X49: =X47-X48 -> 6.5198933e+09
B50: Ch. In NWC | E50: =E49-C49 -> 51493239 | F50: =F49-E49 -> -7.5659738e+08 | G50: =G49-F49 -> 7.5926788e+08 | H50: =H49-G49 -> 5.1168239e+08 | I50: =I49-H49 -> -3.6854398e+08 | J50: =J49-I49 -> -5.2369097e+08 | K50: =K49-J49 -> 6.7568365e+09 | L50: =L49-K49 -> -2.3146335e+09 | M50: =M49-L49 -> -2.2486253e+09 | ... X50: =X49-W49 -> -2.9200504e+09
A52: # | B52: Receivables
B53: No..of days of operation(days) | E53: =360/4 -> 90 | F53: =360/4 -> 90 | G53: =360/4 -> 90 | H53: =360/4 -> 90 | I53: =360/4 -> 90 | J53: =360/4 -> 90 | K53: =360/4 -> 90 | L53: =360/4 -> 90 | ... T53: =360/4 -> 90 | U53: =PL!Y2 -> 75 | V53: =PL!Z2 -> 75 | W53: =PL!AA2 -> 75 | X53: =PL!AB2 -> 75
...

Sheet CFS
B1: No..of days of operation(days) | D1: =300/4 -> 75 | E1: =300/4 -> 75 | F1: =300/4 -> 75 | G1: =300/4 -> 75 | I1: =300/4 -> 75 | J1: =300/4 -> 75 | K1: =300/4 -> 75 | L1: =300/4 -> 75 | N1: =300/4 -> 75 | O1: =300/4 -> 75 | P1: =300/4 -> 75 | Q1: =300/4 -> 75 | S1: =300/4 -> 75 | T1: =300/4 -> 75 | U1: =300/4 -> 75 | V1: =300/4 -> 75 | X1: =300/4 -> 75 | Y1: =300/4 -> 75 | Z1: =300/4 -> 75 | AA1: =300/4 -> 75
B2: Column counter | D2: 1 | E2: =D2+1 -> 2 | F2: =E2+1 -> 3 | G2: =F2+1 -> 4 | I2: =G2+1 -> 5 | J2: =I2+1 -> 6 | K2: =J2+1 -> 7 | L2: =K2+1 -> 8 | N2: =L2+1 -> 9 | O2: =N2+1 -> 10 | P2: =O2+1 -> 11 | Q2: =P2+1 -> 12 | S2: =Q2+1 -> 13 | T2: =S2+1 -> 14 | U2: =T2+1 -> 15 | V2: =U2+1 -> 16 | X2: =V2+1 -> 17 | Y2: =X2+1 -> 18 | Z2: =Y2+1 -> 19 | AA2: =Z2+1 -> 20
B3: Particulars | D3: 45838 | E3: =EOMONTH(D3,3) -> 45930 | F3: =EOMONTH(E3,3) -> 46022 | G3: =EOMONTH(F3,3) -> 46112 | I3: =EOMONTH(G3,3) -> 46203 | J3: =EOMONTH(I3,3) -> 46295 | K3: =EOMONTH(J3,3) -> 46387 | L3: =EOMONTH(K3,3) -> 46477 | N3: =EOMONTH(L3,3) -> 46568 | O3: =EOMONTH(N3,3) -> 46660 | P3: =EOMONTH(O3,3) -> 46752 | Q3: =EOMONTH(P3,3) -> 46843 | S3: =EOMONTH(Q3,3) -> 46934 | T3: =EOMONTH(S3,3) -> 47026 | U3: =EOMONTH(T3,3) -> 47118 | V3: =EOMONTH(U3,3) -> 47208 | X3: =EOMONTH(V3,3) -> 47299 | Y3: =EOMONTH(X3,3) -> 47391 | Z3: =EOMONTH(Y3,3) -> 47483 | AA3: =EOMONTH(Z3,3) -> 47573
A5: # | B5: Cash From Operation
B6: Net Profits | D6: =PL!E53 -> 57938601 | E6: =PL!F53 -> 27364706 | F6: =PL!G53 -> 3.0600423e+08 | G6: =PL!H53 -> 3.7318523e+08 | I6: =PL!J53 -> 3.2207156e+08 | J6: =PL!K53 -> 3.2145327e+08 | K6: =PL!L53 -> 3.7096396e+08 | L6: =PL!M53 -> 6.8677917e+08 | N6: =PL!O53 -> 6.3467164e+08 | O6: =PL!P53 -> 6.0017727e+08 | P6: =PL!Q53 -> 4.8412354e+08 | Q6: =PL!R53 -> 7.5101083e+08 | S6: =PL!T53 -> 6.8871097e+08 | T6: =PL!U53 -> 6.3545882e+08 | U6: =PL!V53 -> 6.3450161e+08 | V6: =PL!W53 -> 8.0469128e+08 | X6: =PL!Y53 -> 7.2535222e+08 | Y6: =PL!Z53 -> 7.0692591e+08 | Z6: =PL!AA53 -> 6.9978356e+08 | AA6: =PL!AB53 -> 8.8242216e+08
B7: Add: D&A | D7: =PL!E46 -> 45302310 | E7: =PL!F46 -> 43603473 | F7: =PL!G46 -> 1.1616368e+08 | G7: =PL!H46 -> 1.1180755e+08 | I7: =PL!J46 -> 1.0761476e+08 | J7: =PL!K46 -> 1.0357921e+08 | K7: =PL!L46 -> 99694990 | L7: =PL!M46 -> 95956427 | N7: =PL!O46 -> 92358061 | O7: =PL!P46 -> 88894634 | P7: =PL!Q46 -> 85561085 | Q7: =PL!R46 -> 82352545 | S7: =PL!T46 -> 79264324 | T7: =PL!U46 -> 76291912 | U7: =PL!V46 -> 73430965 | V7: =PL!W46 -> 70677304 | X7: =PL!Y46 -> 68026905 | Y7: =PL!Z46 -> 65475896 | Z7: =PL!AA46 -> 63020550 | AA7: =PL!AB46 -> 60657280
B8: Add:interest Cost | D8: =PL!E47 -> 93282407 | E8: =PL!F47 -> 98489477 | F8: =PL!G47 -> 95443826 | G8: =PL!H47 -> 92434099 | I8: =PL!J47 -> 89457413 | J8: =PL!K47 -> 86510959 | K8: =PL!L47 -> 83592007 | L8: =PL!M47 -> 21408071 | N8: =PL!O47 -> 20783039 | O8: =PL!P47 -> 20148630 | P8: =PL!Q47 -> 19504706 | Q8: =PL!R47 -> 18851123 | S8: =PL!T47 -> 18187736 | T8: =PL!U47 -> 17514398 | U8: =PL!V47 -> 16830960 | V8: =PL!W47 -> 16137270 | X8: =PL!Y47 -> 15433176 | Y8: =PL!Z47 -> 14718519 | Z8: =PL!AA47 -> 13993143 | AA8: =PL!AB47 -> 13256887
B9: Change in WC | D9: =-BS!E50 -> -51493239 | E9: =-BS!F50 -> 7.5659738e+08 | F9: =-BS!G50 -> -7.5926788e+08 | G9: =-BS!H50 -> -5.1168239e+08 | I9: =-BS!I50 -> 3.6854398e+08 | J9: =-BS!J50 -> 5.2369097e+08 | K9: =-BS!K50 -> -6.7568365e+09 | L9: =-BS!L50 -> 2.3146335e+09 | N9: =-BS!M50 -> 2.2486253e+09 | O9: =-BS!N50 -> 2.1928698e+09 | P9: =-BS!O50 -> -7.1863315e+09 | Q9: =-BS!P50 -> 2.4531843e+09 | S9: =-BS!Q50 -> 2.3839598e+09 | T9: =-BS!R50 -> 2.3192426e+09 | U9: =-BS!S50 -> -7.8650975e+09 | V9: =-BS!T50 -> 2.6861557e+09 | X9: =-BS!U50 -> 2.4746229e+09 | Y9: =-BS!V50 -> 2.5323498e+09 | Z9: =-BS!W50 -> -8.4934752e+09 | AA9: =-BS!X50 -> 2.9200504e+09
B10: Cash From Operation | D10: =SUM(D6:D9) -> 1.4503008e+08 | E10: =SUM(E6:E9) -> 9.2605503e+08 | F10: =SUM(F6:F9) -> -2.4165615e+08 | G10: =SUM(G6:G9) -> 65744491 | I10: =SUM(I6:I9) -> 8.8768771e+08 | J10: =SUM(J6:J9) -> 1.0352344e+09 | K10: =SUM(K6:K9) -> -6.2025855e+09 | L10: =SUM(L6:L9) -> 3.1187772e+09 | N10: =SUM(N6:N9) -> 2.996438e+09 | O10: =SUM(O6:O9) -> 2.9020903e+09 | P10: =SUM(P6:P9) -> -6.5971422e+09 | Q10: =SUM(Q6:Q9) -> 3.3053988e+09 | S10: =SUM(S6:S9) -> 3.1701228e+09 | T10: =SUM(T6:T9) -> 3.0485077e+09 | U10: =SUM(U6:U9) -> -7.140334e+09 | V10: =SUM(V6:V9) -> 3.5776615e+09 | X10: =SUM(X6:X9) -> 3.2834352e+09 | Y10: =SUM(Y6:Y9) -> 3.3194701e+09 | Z10: =SUM(Z6:Z9) -> -7.716678e+09 | AA10: =SUM(AA6:AA9) -> 3.8763867e+09
A12: # | B12: Cash From Investing Activities
B13: Suger and power Plant | D13: =-(BS!E17-BS!C17-BS!E162) -> -7.4505806e-09 | E13: =-(BS!F17-BS!E17-BS!F162) -> 9.6857548e-08 | F13: =-(BS!G17-BS!F17-BS!G162) -> 0 | G13: =-(BS!H17-BS!G17-BS!H162) -> 5.2154064e-08 | I13: =-(BS!I17-BS!H17-BS!I162) -> 5.2154064e-08 | J13: =-(BS!J17-BS!I17-BS!J162) -> 2.9802322e-08 | K13: =-(BS!K17-BS!J17-BS!K162) -> -1.4901161e-08 | L13: =-(BS!L17-BS!K17-BS!L162) -> -2.9802322e-08 | N13: =-(BS!M17-BS!L17-BS!M162) -> -1.8626451e-08 | O13: =-(BS!N17-BS!M17-BS!N162) -> -5.9604645e-08 | P13: =-(BS!O17-BS!N17-BS!O162) -> 5.5879354e-08 | Q13: =-(BS!P17-BS!O17-BS!P162) -> -3.7252903e-08 | S13: =-(BS!Q17-BS!P17-BS!Q162) -> -3.7252903e-09 | T13: =-(BS!R17-BS!Q17-BS!R162) -> -1.1175871e-08 | U13: =-(BS!S17-BS!R17-BS!S162) -> -1.4901161e-08 | V13: =-(BS!T17-BS!S17-BS!T162) -> -4.0978193e-08 | X13: =-(BS!U17-BS!T17-BS!U162) -> -4.4703484e-08 | Y13: =-(BS!V17-BS!U17-BS!V162) -> -1.4901161e-08 | Z13: =-(BS!W17-BS!V17-BS!W162) -> -2.9802322e-08 | AA13: =-(BS!X17-BS!W17-BS!X162) -> 5.2154064e-08
B14: Ethanol Plant | D14: =-(BS!E16-BS!C16-BS!E168) -> 0 | E14: =-(BS!F16-BS!E16-BS!F168) -> -250000000 | F14: =-(BS!G16-BS!F16-BS!G168) -> 4.4703484e-08 | G14: =-(BS!H16-BS!G16-BS!H168) -> 7.4505806e-08 | I14: =-(BS!I16-BS!H16-BS!I168) -> -2.9802322e-08 | J14: =-(BS!J16-BS!I16-BS!J168) -> -6.7055225e-08 | K14: =-(BS!K16-BS!J16-BS!K168) -> -1.4901161e-08 | L14: =-(BS!L16-BS!K16-BS!L168) -> 5.9604645e-08 | N14: =-(BS!M16-BS!L16-BS!M168) -> 1.0430813e-07 | O14: =-(BS!N16-BS!M16-BS!N168) -> -4.4703484e-08 | P14: =-(BS!O16-BS!N16-BS!O168) -> -2.9802322e-08 | Q14: =-(BS!P16-BS!O16-BS!P168) -> -8.1956387e-08 | S14: =-(BS!Q16-BS!P16-BS!Q168) -> 1.1920929e-07 | T14: =-(BS!R16-BS!Q16-BS!R168) -> -8.9406967e-08 | U14: =-(BS!S16-BS!R16-BS!S168) -> -2.2351742e-08 | V14: =-(BS!T16-BS!S16-BS!T168) -> -2.9802322e-08 | X14: =-(BS!U16-BS!T16-BS!U168) -> -4.4703484e-08 | Y14: =-(BS!V16-BS!U16-BS!V168) -> 5.2154064e-08 | Z14: =-(BS!W16-BS!V16-BS!W168) -> -7.4505806e-09 | AA14: =-(BS!X16-BS!W16-BS!X168) -> -5.2154064e-08
B15: Cash From Investing Activities | D15: =SUM(D13:D14) -> -7.4505806e-09 | E15: =SUM(E13:E14) -> -2.5e+08 | F15: =SUM(F13:F14) -> 4.4703484e-08 | G15: =SUM(G13:G14) -> 1.2665987e-07 | I15: =SUM(I13:I14) -> 2.2351742e-08 | J15: =SUM(J13:J14) -> -3.7252903e-08 | K15: =SUM(K13:K14) -> -2.9802322e-08 | L15: =SUM(L13:L14) -> 2.9802322e-08 | N15: =SUM(N13:N14) -> 8.5681677e-08 | O15: =SUM(O13:O14) -> -1.0430813e-07 | P15: =SUM(P13:P14) -> 2.6077032e-08 | Q15: =SUM(Q13:Q14) -> -1.1920929e-07 | S15: =SUM(S13:S14) -> 1.15484e-07 | T15: =SUM(T13:T14) -> -1.0058284e-07 | U15: =SUM(U13:U14) -> -3.7252903e-08 | V15: =SUM(V13:V14) -> -7.0780516e-08 | X15: =SUM(X13:X14) -> -8.9406967e-08 | Y15: =SUM(Y13:Y14) -> 3.7252903e-08 | Z15: =SUM(Z13:Z14) -> -3.7252903e-08 | AA15: =SUM(AA13:AA14) -> 0
A17: # | B17: Cash From Financing Activities
